Traceback (most recent call last):
  File "/home5/edumetrics/Edumetrics/Edumetrics/passenger_wsgi.py", line 8, in <module>
    wsgi = imp.load_source('wsgi', 'Edumetrics/wsgi.py')
  File "/opt/alt/python310/lib64/python3.10/imp.py", line 172, in load_source
    module = _load(spec)
  File "<frozen importlib._bootstrap>", line 719, in _load
  File "<frozen importlib._bootstrap>", line 688, in _load_unlocked
  File "<frozen importlib._bootstrap_external>", line 879, in exec_module
  File "<frozen importlib._bootstrap_external>", line 1017, in get_code
  File "<frozen importlib._bootstrap_external>", line 947, in source_to_code
  File "<frozen importlib._bootstrap>", line 241, in _call_with_frames_removed
  File "Edumetrics/wsgi.py", line 8
    def Edumetrics/wsgi.py(environ, start_response):
                  ^
SyntaxError: invalid syntax
Traceback (most recent call last):
  File "/home5/edumetrics/Edumetrics/Edumetrics/passenger_wsgi.py", line 8, in <module>
    wsgi = imp.load_source('wsgi', 'Edumetrics/wsgi.py')
  File "/opt/alt/python310/lib64/python3.10/imp.py", line 172, in load_source
    module = _load(spec)
  File "<frozen importlib._bootstrap>", line 719, in _load
  File "<frozen importlib._bootstrap>", line 688, in _load_unlocked
  File "<frozen importlib._bootstrap_external>", line 879, in exec_module
  File "<frozen importlib._bootstrap_external>", line 1017, in get_code
  File "<frozen importlib._bootstrap_external>", line 947, in source_to_code
  File "<frozen importlib._bootstrap>", line 241, in _call_with_frames_removed
  File "Edumetrics/wsgi.py", line 8
    def Edumetrics/wsgi.py(environ, start_response):
                  ^
SyntaxError: invalid syntax
[UID:4478][11937] Child process with pid: 11957 was killed by signal: 15, core dumped: no
Traceback (most recent call last):
  File "/home5/edumetrics/Edumetrics/Edumetrics/passenger_wsgi.py", line 8, in <module>
    wsgi = imp.load_source('wsgi', 'Edumetrics/wsgi.py')
  File "/opt/alt/python310/lib64/python3.10/imp.py", line 172, in load_source
    module = _load(spec)
  File "<frozen importlib._bootstrap>", line 719, in _load
  File "<frozen importlib._bootstrap>", line 688, in _load_unlocked
  File "<frozen importlib._bootstrap_external>", line 879, in exec_module
  File "<frozen importlib._bootstrap_external>", line 1017, in get_code
  File "<frozen importlib._bootstrap_external>", line 947, in source_to_code
  File "<frozen importlib._bootstrap>", line 241, in _call_with_frames_removed
  File "Edumetrics/wsgi.py", line 8
    def Edumetrics/wsgi.py(environ, start_response):
                  ^
SyntaxError: invalid syntax
[UID:4478][11937] Child process with pid: 15763 was killed by signal: 15, core dumped: no
Traceback (most recent call last):
  File "/home5/edumetrics/Edumetrics/Edumetrics/passenger_wsgi.py", line 8, in <module>
    wsgi = imp.load_source('wsgi', 'Edumetrics/wsgi.py')
  File "/opt/alt/python310/lib64/python3.10/imp.py", line 172, in load_source
    module = _load(spec)
  File "<frozen importlib._bootstrap>", line 719, in _load
  File "<frozen importlib._bootstrap>", line 688, in _load_unlocked
  File "<frozen importlib._bootstrap_external>", line 879, in exec_module
  File "<frozen importlib._bootstrap_external>", line 1017, in get_code
  File "<frozen importlib._bootstrap_external>", line 947, in source_to_code
  File "<frozen importlib._bootstrap>", line 241, in _call_with_frames_removed
  File "Edumetrics/wsgi.py", line 8
    def Edumetrics/wsgi.py(environ, start_response):
                  ^
SyntaxError: invalid syntax
Traceback (most recent call last):
  File "/home5/edumetrics/Edumetrics/Edumetrics/passenger_wsgi.py", line 8, in <module>
    wsgi = imp.load_source('wsgi', 'Edumetrics/wsgi.py')
  File "/opt/alt/python310/lib64/python3.10/imp.py", line 172, in load_source
    module = _load(spec)
  File "<frozen importlib._bootstrap>", line 719, in _load
  File "<frozen importlib._bootstrap>", line 688, in _load_unlocked
  File "<frozen importlib._bootstrap_external>", line 879, in exec_module
  File "<frozen importlib._bootstrap_external>", line 1017, in get_code
  File "<frozen importlib._bootstrap_external>", line 947, in source_to_code
  File "<frozen importlib._bootstrap>", line 241, in _call_with_frames_removed
  File "Edumetrics/wsgi.py", line 8
    def Edumetrics/wsgi.py(environ, start_response):
                  ^
SyntaxError: invalid syntax
[UID:4478][21552] Child process with pid: 21568 was killed by signal: 15, core dumped: no
Traceback (most recent call last):
  File "/home5/edumetrics/Edumetrics/Edumetrics/passenger_wsgi.py", line 8, in <module>
    wsgi = imp.load_source('wsgi', 'Edumetrics/wsgi.py')
  File "/opt/alt/python310/lib64/python3.10/imp.py", line 172, in load_source
    module = _load(spec)
  File "<frozen importlib._bootstrap>", line 719, in _load
  File "<frozen importlib._bootstrap>", line 688, in _load_unlocked
  File "<frozen importlib._bootstrap_external>", line 879, in exec_module
  File "<frozen importlib._bootstrap_external>", line 1017, in get_code
  File "<frozen importlib._bootstrap_external>", line 947, in source_to_code
  File "<frozen importlib._bootstrap>", line 241, in _call_with_frames_removed
  File "Edumetrics/wsgi.py", line 8
    def Edumetrics/wsgi.py(environ, start_response):
                  ^
SyntaxError: invalid syntax
[UID:4478][21552] Child process with pid: 27838 was killed by signal: 15, core dumped: no
Traceback (most recent call last):
  File "/home5/edumetrics/Edumetrics/Edumetrics/passenger_wsgi.py", line 8, in <module>
    wsgi = imp.load_source('wsgi', 'Edumetrics/wsgi.py')
  File "/opt/alt/python310/lib64/python3.10/imp.py", line 172, in load_source
    module = _load(spec)
  File "<frozen importlib._bootstrap>", line 719, in _load
  File "<frozen importlib._bootstrap>", line 688, in _load_unlocked
  File "<frozen importlib._bootstrap_external>", line 879, in exec_module
  File "<frozen importlib._bootstrap_external>", line 1017, in get_code
  File "<frozen importlib._bootstrap_external>", line 947, in source_to_code
  File "<frozen importlib._bootstrap>", line 241, in _call_with_frames_removed
  File "Edumetrics/wsgi.py", line 8
    def Edumetrics/wsgi.py(environ, start_response):
                  ^
SyntaxError: invalid syntax
[UID:4478][21552] Child process with pid: 27961 was killed by signal: 15, core dumped: no
Traceback (most recent call last):
  File "/home5/edumetrics/Edumetrics/Edumetrics/passenger_wsgi.py", line 8, in <module>
    wsgi = imp.load_source('wsgi', 'Edumetrics.wsgi.py')
  File "/opt/alt/python310/lib64/python3.10/imp.py", line 172, in load_source
    module = _load(spec)
  File "<frozen importlib._bootstrap>", line 719, in _load
  File "<frozen importlib._bootstrap>", line 688, in _load_unlocked
  File "<frozen importlib._bootstrap_external>", line 879, in exec_module
  File "<frozen importlib._bootstrap_external>", line 1016, in get_code
  File "/opt/alt/python310/lib64/python3.10/imp.py", line 158, in get_data
    return super().get_data(path)
  File "<frozen importlib._bootstrap_external>", line 1073, in get_data
FileNotFoundError: [Errno 2] No such file or directory: 'Edumetrics.wsgi.py'
Traceback (most recent call last):
  File "/home5/edumetrics/Edumetrics/Edumetrics/passenger_wsgi.py", line 8, in <module>
    wsgi = imp.load_source('wsgi', 'Edumetrics.wsgi.py')
  File "/opt/alt/python310/lib64/python3.10/imp.py", line 172, in load_source
    module = _load(spec)
  File "<frozen importlib._bootstrap>", line 719, in _load
  File "<frozen importlib._bootstrap>", line 688, in _load_unlocked
  File "<frozen importlib._bootstrap_external>", line 879, in exec_module
  File "<frozen importlib._bootstrap_external>", line 1016, in get_code
  File "/opt/alt/python310/lib64/python3.10/imp.py", line 158, in get_data
    return super().get_data(path)
  File "<frozen importlib._bootstrap_external>", line 1073, in get_data
FileNotFoundError: [Errno 2] No such file or directory: 'Edumetrics.wsgi.py'
[UID:4478][6150] Child process with pid: 6167 was killed by signal: 15, core dumped: no
Traceback (most recent call last):
  File "/home5/edumetrics/Edumetrics/Edumetrics/passenger_wsgi.py", line 8, in <module>
    wsgi = imp.load_source('wsgi', 'Edumetrics/wsgi.py')
  File "/opt/alt/python310/lib64/python3.10/imp.py", line 172, in load_source
    module = _load(spec)
  File "<frozen importlib._bootstrap>", line 719, in _load
  File "<frozen importlib._bootstrap>", line 688, in _load_unlocked
  File "<frozen importlib._bootstrap_external>", line 879, in exec_module
  File "<frozen importlib._bootstrap_external>", line 1017, in get_code
  File "<frozen importlib._bootstrap_external>", line 947, in source_to_code
  File "<frozen importlib._bootstrap>", line 241, in _call_with_frames_removed
  File "Edumetrics/wsgi.py", line 8
    def Edumetrics/wsgi.py(environ, start_response):
                  ^
SyntaxError: invalid syntax
Traceback (most recent call last):
  File "/home5/edumetrics/Edumetrics/Edumetrics/passenger_wsgi.py", line 8, in <module>
    wsgi = imp.load_source('wsgi', 'Edumetrics/wsgi.py')
  File "/opt/alt/python310/lib64/python3.10/imp.py", line 172, in load_source
    module = _load(spec)
  File "<frozen importlib._bootstrap>", line 719, in _load
  File "<frozen importlib._bootstrap>", line 688, in _load_unlocked
  File "<frozen importlib._bootstrap_external>", line 879, in exec_module
  File "<frozen importlib._bootstrap_external>", line 1017, in get_code
  File "<frozen importlib._bootstrap_external>", line 947, in source_to_code
  File "<frozen importlib._bootstrap>", line 241, in _call_with_frames_removed
  File "Edumetrics/wsgi.py", line 8
    def Edumetrics/wsgi.py(environ, start_response):
                  ^
SyntaxError: invalid syntax
[UID:4478][18873] Child process with pid: 18900 was killed by signal: 15, core dumped: no
Traceback (most recent call last):
  File "/home5/edumetrics/Edumetrics/Edumetrics/passenger_wsgi.py", line 8, in <module>
    wsgi = imp.load_source('wsgi', 'Edumetrics/wsgi.py')
  File "/opt/alt/python310/lib64/python3.10/imp.py", line 172, in load_source
    module = _load(spec)
  File "<frozen importlib._bootstrap>", line 719, in _load
  File "<frozen importlib._bootstrap>", line 688, in _load_unlocked
  File "<frozen importlib._bootstrap_external>", line 879, in exec_module
  File "<frozen importlib._bootstrap_external>", line 1017, in get_code
  File "<frozen importlib._bootstrap_external>", line 947, in source_to_code
  File "<frozen importlib._bootstrap>", line 241, in _call_with_frames_removed
  File "Edumetrics/wsgi.py", line 8
    def Edumetrics.wsgi.py(environ, start_response):
                  ^
SyntaxError: invalid syntax
Traceback (most recent call last):
  File "/home5/edumetrics/Edumetrics/Edumetrics/passenger_wsgi.py", line 8, in <module>
    wsgi = imp.load_source('wsgi', 'Edumetrics/wsgi.py')
  File "/opt/alt/python310/lib64/python3.10/imp.py", line 172, in load_source
    module = _load(spec)
  File "<frozen importlib._bootstrap>", line 719, in _load
  File "<frozen importlib._bootstrap>", line 688, in _load_unlocked
  File "<frozen importlib._bootstrap_external>", line 879, in exec_module
  File "<frozen importlib._bootstrap_external>", line 1017, in get_code
  File "<frozen importlib._bootstrap_external>", line 947, in source_to_code
  File "<frozen importlib._bootstrap>", line 241, in _call_with_frames_removed
  File "Edumetrics/wsgi.py", line 8
    def Edumetrics.wsgi.py(environ, start_response):
                  ^
SyntaxError: invalid syntax
[UID:4478][4641] Child process with pid: 4652 was killed by signal: 15, core dumped: no
Traceback (most recent call last):
  File "/home5/edumetrics/Edumetrics/Edumetrics/passenger_wsgi.py", line 8, in <module>
    wsgi = imp.load_source('wsgi', 'Edumetrics/wsgi.py')
  File "/opt/alt/python310/lib64/python3.10/imp.py", line 172, in load_source
    module = _load(spec)
  File "<frozen importlib._bootstrap>", line 719, in _load
  File "<frozen importlib._bootstrap>", line 688, in _load_unlocked
  File "<frozen importlib._bootstrap_external>", line 879, in exec_module
  File "<frozen importlib._bootstrap_external>", line 1017, in get_code
  File "<frozen importlib._bootstrap_external>", line 947, in source_to_code
  File "<frozen importlib._bootstrap>", line 241, in _call_with_frames_removed
  File "Edumetrics/wsgi.py", line 8
    def Edumetrics.wsgi.py(environ, start_response):
                  ^
SyntaxError: invalid syntax
Traceback (most recent call last):
  File "/home5/edumetrics/Edumetrics/Edumetrics/passenger_wsgi.py", line 8, in <module>
    wsgi = imp.load_source('wsgi', 'Edumetrics/wsgi.py')
  File "/opt/alt/python310/lib64/python3.10/imp.py", line 172, in load_source
    module = _load(spec)
  File "<frozen importlib._bootstrap>", line 719, in _load
  File "<frozen importlib._bootstrap>", line 688, in _load_unlocked
  File "<frozen importlib._bootstrap_external>", line 879, in exec_module
  File "<frozen importlib._bootstrap_external>", line 1017, in get_code
  File "<frozen importlib._bootstrap_external>", line 947, in source_to_code
  File "<frozen importlib._bootstrap>", line 241, in _call_with_frames_removed
  File "Edumetrics/wsgi.py", line 8
    def Edumetrics.wsgi.py(environ, start_response):
                  ^
SyntaxError: invalid syntax
[UID:4478][7366] Child process with pid: 7655 was killed by signal: 15, core dumped: no
Traceback (most recent call last):
  File "/home5/edumetrics/Edumetrics/Edumetrics/passenger_wsgi.py", line 9, in <module>
    application = wsgi.Edumetrics.wsgi.py
AttributeError: module 'wsgi' has no attribute 'Edumetrics'
[UID:4478][7366] Child process with pid: 16284 was killed by signal: 15, core dumped: no
Invalid HTTP_HOST header: 'edu-metrics.com'. You may need to add 'edu-metrics.com' to ALLOWED_HOSTS.
Bad Request: /
Invalid HTTP_HOST header: 'edu-metrics.com'. You may need to add 'edu-metrics.com' to ALLOWED_HOSTS.
Bad Request: /
Invalid HTTP_HOST header: 'edu-metrics.com'. You may need to add 'edu-metrics.com' to ALLOWED_HOSTS.
Bad Request: /
Invalid HTTP_HOST header: 'edu-metrics.com'. You may need to add 'edu-metrics.com' to ALLOWED_HOSTS.
Bad Request: /
Invalid HTTP_HOST header: 'edu-metrics.com'. You may need to add 'edu-metrics.com' to ALLOWED_HOSTS.
Bad Request: /
Invalid HTTP_HOST header: 'edu-metrics.com'. You may need to add 'edu-metrics.com' to ALLOWED_HOSTS.
Bad Request: /
Invalid HTTP_HOST header: 'edu-metrics.com'. You may need to add 'edu-metrics.com' to ALLOWED_HOSTS.
Bad Request: /
Not Found: /img/favicon.ico
Not Found: /img/favicon.ico
Not Found: /auth/admin-login/img/favicon.ico
Not Found: /auth/forgot-password/img/favicon.ico
Not Found: /auth/reset-password/8/img/favicon.ico
Not Found: /auth/signup/img/favicon.ico
Invalid HTTP_HOST header: 'www.edu-metrics.com'. You may need to add 'www.edu-metrics.com' to ALLOWED_HOSTS.
Bad Request: /
Not Found: //static/js/next.js
Not Found: //static/lib/wow/wow.min.js
Not Found: //static/lib/easing/easing.min.js
Not Found: //static/lib/waypoints/waypoints.min.js
Not Found: //static/lib/owlcarousel/owl.carousel.min.js
Not Found: //static/js/main.js
Not Found: /robots.txt
Not Found: /index.html
Not Found: /index.html
Not Found: /index.html
Not Found: /img/favicon.ico
Invalid HTTP_HOST header: 'www.edu-metrics.com'. You may need to add 'www.edu-metrics.com' to ALLOWED_HOSTS.
Bad Request: /
Not Found: /robots.txt
Not Found: /img/favicon.ico
Not Found: /auth/admin-login/img/favicon.ico
Not Found: /school-admin/dashboard/img/favicon.ico
Not Found: /img/favicon.ico
Traceback (most recent call last):
  File "/home5/edumetrics/virtualenv/Edumetrics/Edumetrics/3.10/lib/python3.10/site-packages/django/db/backends/mysql/base.py", line 15, in <module>
    import MySQLdb as Database
ModuleNotFoundError: No module named 'MySQLdb'

The above exception was the direct cause of the following exception:

Traceback (most recent call last):
  File "/home5/edumetrics/Edumetrics/Edumetrics/passenger_wsgi.py", line 4, in <module>
    from Edumetrics.wsgi import application
  File "/home5/edumetrics/Edumetrics/Edumetrics/Edumetrics/wsgi.py", line 16, in <module>
    application = get_wsgi_application()
  File "/home5/edumetrics/virtualenv/Edumetrics/Edumetrics/3.10/lib/python3.10/site-packages/django/core/wsgi.py", line 12, in get_wsgi_application
    django.setup(set_prefix=False)
  File "/home5/edumetrics/virtualenv/Edumetrics/Edumetrics/3.10/lib/python3.10/site-packages/django/__init__.py", line 24, in setup
    apps.populate(settings.INSTALLED_APPS)
  File "/home5/edumetrics/virtualenv/Edumetrics/Edumetrics/3.10/lib/python3.10/site-packages/django/apps/registry.py", line 114, in populate
    app_config.import_models()
  File "/home5/edumetrics/virtualenv/Edumetrics/Edumetrics/3.10/lib/python3.10/site-packages/django/apps/config.py", line 301, in import_models
    self.models_module = import_module(models_module_name)
  File "/opt/alt/python310/lib64/python3.10/importlib/__init__.py", line 126, in import_module
    return _bootstrap._gcd_import(name[level:], package, level)
  File "/home5/edumetrics/virtualenv/Edumetrics/Edumetrics/3.10/lib/python3.10/site-packages/django/contrib/auth/models.py", line 3, in <module>
    from django.contrib.auth.base_user import AbstractBaseUser, BaseUserManager
  File "/home5/edumetrics/virtualenv/Edumetrics/Edumetrics/3.10/lib/python3.10/site-packages/django/contrib/auth/base_user.py", line 48, in <module>
    class AbstractBaseUser(models.Model):
  File "/home5/edumetrics/virtualenv/Edumetrics/Edumetrics/3.10/lib/python3.10/site-packages/django/db/models/base.py", line 122, in __new__
    new_class.add_to_class('_meta', Options(meta, app_label))
  File "/home5/edumetrics/virtualenv/Edumetrics/Edumetrics/3.10/lib/python3.10/site-packages/django/db/models/base.py", line 326, in add_to_class
    value.contribute_to_class(cls, name)
  File "/home5/edumetrics/virtualenv/Edumetrics/Edumetrics/3.10/lib/python3.10/site-packages/django/db/models/options.py", line 207, in contribute_to_class
    self.db_table = truncate_name(self.db_table, connection.ops.max_name_length())
  File "/home5/edumetrics/virtualenv/Edumetrics/Edumetrics/3.10/lib/python3.10/site-packages/django/utils/connection.py", line 15, in __getattr__
    return getattr(self._connections[self._alias], item)
  File "/home5/edumetrics/virtualenv/Edumetrics/Edumetrics/3.10/lib/python3.10/site-packages/django/utils/connection.py", line 62, in __getitem__
    conn = self.create_connection(alias)
  File "/home5/edumetrics/virtualenv/Edumetrics/Edumetrics/3.10/lib/python3.10/site-packages/django/db/utils.py", line 204, in create_connection
    backend = load_backend(db['ENGINE'])
  File "/home5/edumetrics/virtualenv/Edumetrics/Edumetrics/3.10/lib/python3.10/site-packages/django/db/utils.py", line 111, in load_backend
    return import_module('%s.base' % backend_name)
  File "/opt/alt/python310/lib64/python3.10/importlib/__init__.py", line 126, in import_module
    return _bootstrap._gcd_import(name[level:], package, level)
  File "/home5/edumetrics/virtualenv/Edumetrics/Edumetrics/3.10/lib/python3.10/site-packages/django/db/backends/mysql/base.py", line 17, in <module>
    raise ImproperlyConfigured(
django.core.exceptions.ImproperlyConfigured: Error loading MySQLdb module.
Did you install mysqlclient?
Traceback (most recent call last):
  File "/home5/edumetrics/Edumetrics/Edumetrics/passenger_wsgi.py", line 4, in <module>
    from Edumetrics.wsgi import application
  File "/home5/edumetrics/Edumetrics/Edumetrics/Edumetrics/wsgi.py", line 16, in <module>
    application = get_wsgi_application()
  File "/home5/edumetrics/virtualenv/Edumetrics/Edumetrics/3.10/lib/python3.10/site-packages/django/core/wsgi.py", line 12, in get_wsgi_application
    django.setup(set_prefix=False)
  File "/home5/edumetrics/virtualenv/Edumetrics/Edumetrics/3.10/lib/python3.10/site-packages/django/__init__.py", line 24, in setup
    apps.populate(settings.INSTALLED_APPS)
  File "/home5/edumetrics/virtualenv/Edumetrics/Edumetrics/3.10/lib/python3.10/site-packages/django/apps/registry.py", line 83, in populate
    raise RuntimeError("populate() isn't reentrant")
RuntimeError: populate() isn't reentrant
[UID:4478][27189] Child process with pid: 27293 was killed by signal: 15, core dumped: no
Traceback (most recent call last):
  File "/home5/edumetrics/Edumetrics/Edumetrics/passenger_wsgi.py", line 4, in <module>
    from Edumetrics.wsgi import application
  File "/home5/edumetrics/Edumetrics/Edumetrics/Edumetrics/wsgi.py", line 16, in <module>
    application = get_wsgi_application()
  File "/home5/edumetrics/virtualenv/Edumetrics/Edumetrics/3.10/lib/python3.10/site-packages/django/core/wsgi.py", line 12, in get_wsgi_application
    django.setup(set_prefix=False)
  File "/home5/edumetrics/virtualenv/Edumetrics/Edumetrics/3.10/lib/python3.10/site-packages/django/__init__.py", line 24, in setup
    apps.populate(settings.INSTALLED_APPS)
  File "/home5/edumetrics/virtualenv/Edumetrics/Edumetrics/3.10/lib/python3.10/site-packages/django/apps/registry.py", line 83, in populate
    raise RuntimeError("populate() isn't reentrant")
RuntimeError: populate() isn't reentrant
[UID:4478][27189] Child process with pid: 27730 was killed by signal: 15, core dumped: no
Traceback (most recent call last):
  File "/home5/edumetrics/Edumetrics/Edumetrics/passenger_wsgi.py", line 4, in <module>
    from Edumetrics.wsgi import application
  File "/home5/edumetrics/Edumetrics/Edumetrics/Edumetrics/wsgi.py", line 16, in <module>
    application = get_wsgi_application()
  File "/home5/edumetrics/virtualenv/Edumetrics/Edumetrics/3.10/lib/python3.10/site-packages/django/core/wsgi.py", line 12, in get_wsgi_application
    django.setup(set_prefix=False)
  File "/home5/edumetrics/virtualenv/Edumetrics/Edumetrics/3.10/lib/python3.10/site-packages/django/__init__.py", line 24, in setup
    apps.populate(settings.INSTALLED_APPS)
  File "/home5/edumetrics/virtualenv/Edumetrics/Edumetrics/3.10/lib/python3.10/site-packages/django/apps/registry.py", line 83, in populate
    raise RuntimeError("populate() isn't reentrant")
RuntimeError: populate() isn't reentrant
[UID:4478][27189] Child process with pid: 9930 was killed by signal: 15, core dumped: no
Internal Server Error: /school-admin/dashboard/
Traceback (most recent call last):
  File "/home5/edumetrics/virtualenv/Edumetrics/Edumetrics/3.10/lib/python3.10/site-packages/django/contrib/sessions/backends/base.py", line 233, in _get_session
    return self._session_cache
AttributeError: 'SessionStore' object has no attribute '_session_cache'

During handling of the above exception, another exception occurred:

Traceback (most recent call last):
  File "/home5/edumetrics/virtualenv/Edumetrics/Edumetrics/3.10/lib/python3.10/site-packages/django/db/backends/base/base.py", line 219, in ensure_connection
    self.connect()
  File "/home5/edumetrics/virtualenv/Edumetrics/Edumetrics/3.10/lib/python3.10/site-packages/django/utils/asyncio.py", line 26, in inner
    return func(*args, **kwargs)
  File "/home5/edumetrics/virtualenv/Edumetrics/Edumetrics/3.10/lib/python3.10/site-packages/django/db/backends/base/base.py", line 200, in connect
    self.connection = self.get_new_connection(conn_params)
  File "/home5/edumetrics/virtualenv/Edumetrics/Edumetrics/3.10/lib/python3.10/site-packages/django/utils/asyncio.py", line 26, in inner
    return func(*args, **kwargs)
  File "/home5/edumetrics/virtualenv/Edumetrics/Edumetrics/3.10/lib/python3.10/site-packages/django/db/backends/mysql/base.py", line 234, in get_new_connection
    connection = Database.connect(**conn_params)
  File "/home5/edumetrics/virtualenv/Edumetrics/Edumetrics/3.10/lib64/python3.10/site-packages/MySQLdb/__init__.py", line 123, in Connect
    return Connection(*args, **kwargs)
  File "/home5/edumetrics/virtualenv/Edumetrics/Edumetrics/3.10/lib64/python3.10/site-packages/MySQLdb/connections.py", line 185, in __init__
    super().__init__(*args, **kwargs2)
MySQLdb.OperationalError: (1045, "Access denied for user 'edumetrics_user'@'localhost' (using password: YES)")

The above exception was the direct cause of the following exception:

Traceback (most recent call last):
  File "/home5/edumetrics/virtualenv/Edumetrics/Edumetrics/3.10/lib/python3.10/site-packages/django/core/handlers/exception.py", line 47, in inner
    response = get_response(request)
  File "/home5/edumetrics/virtualenv/Edumetrics/Edumetrics/3.10/lib/python3.10/site-packages/django/core/handlers/base.py", line 181, in _get_response
    response = wrapped_callback(request, *callback_args, **callback_kwargs)
  File "/home5/edumetrics/virtualenv/Edumetrics/Edumetrics/3.10/lib/python3.10/site-packages/django/contrib/auth/decorators.py", line 20, in _wrapped_view
    if test_func(request.user):
  File "/home5/edumetrics/virtualenv/Edumetrics/Edumetrics/3.10/lib/python3.10/site-packages/django/contrib/auth/decorators.py", line 44, in <lambda>
    lambda u: u.is_authenticated,
  File "/home5/edumetrics/virtualenv/Edumetrics/Edumetrics/3.10/lib/python3.10/site-packages/django/utils/functional.py", line 246, in inner
    self._setup()
  File "/home5/edumetrics/virtualenv/Edumetrics/Edumetrics/3.10/lib/python3.10/site-packages/django/utils/functional.py", line 382, in _setup
    self._wrapped = self._setupfunc()
  File "/home5/edumetrics/virtualenv/Edumetrics/Edumetrics/3.10/lib/python3.10/site-packages/django/contrib/auth/middleware.py", line 23, in <lambda>
    request.user = SimpleLazyObject(lambda: get_user(request))
  File "/home5/edumetrics/virtualenv/Edumetrics/Edumetrics/3.10/lib/python3.10/site-packages/django/contrib/auth/middleware.py", line 11, in get_user
    request._cached_user = auth.get_user(request)
  File "/home5/edumetrics/virtualenv/Edumetrics/Edumetrics/3.10/lib/python3.10/site-packages/django/contrib/auth/__init__.py", line 177, in get_user
    user_id = _get_user_session_key(request)
  File "/home5/edumetrics/virtualenv/Edumetrics/Edumetrics/3.10/lib/python3.10/site-packages/django/contrib/auth/__init__.py", line 60, in _get_user_session_key
    return get_user_model()._meta.pk.to_python(request.session[SESSION_KEY])
  File "/home5/edumetrics/virtualenv/Edumetrics/Edumetrics/3.10/lib/python3.10/site-packages/django/contrib/sessions/backends/base.py", line 65, in __getitem__
    return self._session[key]
  File "/home5/edumetrics/virtualenv/Edumetrics/Edumetrics/3.10/lib/python3.10/site-packages/django/contrib/sessions/backends/base.py", line 238, in _get_session
    self._session_cache = self.load()
  File "/home5/edumetrics/virtualenv/Edumetrics/Edumetrics/3.10/lib/python3.10/site-packages/django/contrib/sessions/backends/db.py", line 43, in load
    s = self._get_session_from_db()
  File "/home5/edumetrics/virtualenv/Edumetrics/Edumetrics/3.10/lib/python3.10/site-packages/django/contrib/sessions/backends/db.py", line 32, in _get_session_from_db
    return self.model.objects.get(
  File "/home5/edumetrics/virtualenv/Edumetrics/Edumetrics/3.10/lib/python3.10/site-packages/django/db/models/manager.py", line 85, in manager_method
    return getattr(self.get_queryset(), name)(*args, **kwargs)
  File "/home5/edumetrics/virtualenv/Edumetrics/Edumetrics/3.10/lib/python3.10/site-packages/django/db/models/query.py", line 431, in get
    num = len(clone)
  File "/home5/edumetrics/virtualenv/Edumetrics/Edumetrics/3.10/lib/python3.10/site-packages/django/db/models/query.py", line 262, in __len__
    self._fetch_all()
  File "/home5/edumetrics/virtualenv/Edumetrics/Edumetrics/3.10/lib/python3.10/site-packages/django/db/models/query.py", line 1324, in _fetch_all
    self._result_cache = list(self._iterable_class(self))
  File "/home5/edumetrics/virtualenv/Edumetrics/Edumetrics/3.10/lib/python3.10/site-packages/django/db/models/query.py", line 51, in __iter__
    results = compiler.execute_sql(chunked_fetch=self.chunked_fetch, chunk_size=self.chunk_size)
  File "/home5/edumetrics/virtualenv/Edumetrics/Edumetrics/3.10/lib/python3.10/site-packages/django/db/models/sql/compiler.py", line 1167, in execute_sql
    cursor = self.connection.cursor()
  File "/home5/edumetrics/virtualenv/Edumetrics/Edumetrics/3.10/lib/python3.10/site-packages/django/utils/asyncio.py", line 26, in inner
    return func(*args, **kwargs)
  File "/home5/edumetrics/virtualenv/Edumetrics/Edumetrics/3.10/lib/python3.10/site-packages/django/db/backends/base/base.py", line 259, in cursor
    return self._cursor()
  File "/home5/edumetrics/virtualenv/Edumetrics/Edumetrics/3.10/lib/python3.10/site-packages/django/db/backends/base/base.py", line 235, in _cursor
    self.ensure_connection()
  File "/home5/edumetrics/virtualenv/Edumetrics/Edumetrics/3.10/lib/python3.10/site-packages/django/utils/asyncio.py", line 26, in inner
    return func(*args, **kwargs)
  File "/home5/edumetrics/virtualenv/Edumetrics/Edumetrics/3.10/lib/python3.10/site-packages/django/db/backends/base/base.py", line 218, in ensure_connection
    with self.wrap_database_errors:
  File "/home5/edumetrics/virtualenv/Edumetrics/Edumetrics/3.10/lib/python3.10/site-packages/django/db/utils.py", line 90, in __exit__
    raise dj_exc_value.with_traceback(traceback) from exc_value
  File "/home5/edumetrics/virtualenv/Edumetrics/Edumetrics/3.10/lib/python3.10/site-packages/django/db/backends/base/base.py", line 219, in ensure_connection
    self.connect()
  File "/home5/edumetrics/virtualenv/Edumetrics/Edumetrics/3.10/lib/python3.10/site-packages/django/utils/asyncio.py", line 26, in inner
    return func(*args, **kwargs)
  File "/home5/edumetrics/virtualenv/Edumetrics/Edumetrics/3.10/lib/python3.10/site-packages/django/db/backends/base/base.py", line 200, in connect
    self.connection = self.get_new_connection(conn_params)
  File "/home5/edumetrics/virtualenv/Edumetrics/Edumetrics/3.10/lib/python3.10/site-packages/django/utils/asyncio.py", line 26, in inner
    return func(*args, **kwargs)
  File "/home5/edumetrics/virtualenv/Edumetrics/Edumetrics/3.10/lib/python3.10/site-packages/django/db/backends/mysql/base.py", line 234, in get_new_connection
    connection = Database.connect(**conn_params)
  File "/home5/edumetrics/virtualenv/Edumetrics/Edumetrics/3.10/lib64/python3.10/site-packages/MySQLdb/__init__.py", line 123, in Connect
    return Connection(*args, **kwargs)
  File "/home5/edumetrics/virtualenv/Edumetrics/Edumetrics/3.10/lib64/python3.10/site-packages/MySQLdb/connections.py", line 185, in __init__
    super().__init__(*args, **kwargs2)
django.db.utils.OperationalError: (1045, "Access denied for user 'edumetrics_user'@'localhost' (using password: YES)")
Not Found: /favicon.ico
Internal Server Error: /school-admin/dashboard/
Traceback (most recent call last):
  File "/home5/edumetrics/virtualenv/Edumetrics/Edumetrics/3.10/lib/python3.10/site-packages/django/contrib/sessions/backends/base.py", line 233, in _get_session
    return self._session_cache
AttributeError: 'SessionStore' object has no attribute '_session_cache'

During handling of the above exception, another exception occurred:

Traceback (most recent call last):
  File "/home5/edumetrics/virtualenv/Edumetrics/Edumetrics/3.10/lib/python3.10/site-packages/django/db/backends/utils.py", line 84, in _execute
    return self.cursor.execute(sql, params)
  File "/home5/edumetrics/virtualenv/Edumetrics/Edumetrics/3.10/lib/python3.10/site-packages/django/db/backends/mysql/base.py", line 73, in execute
    return self.cursor.execute(query, args)
  File "/home5/edumetrics/virtualenv/Edumetrics/Edumetrics/3.10/lib64/python3.10/site-packages/MySQLdb/cursors.py", line 206, in execute
    res = self._query(query)
  File "/home5/edumetrics/virtualenv/Edumetrics/Edumetrics/3.10/lib64/python3.10/site-packages/MySQLdb/cursors.py", line 319, in _query
    db.query(q)
  File "/home5/edumetrics/virtualenv/Edumetrics/Edumetrics/3.10/lib64/python3.10/site-packages/MySQLdb/connections.py", line 254, in query
    _mysql.connection.query(self, query)
MySQLdb.ProgrammingError: (1146, "Table 'edumetrics_database.django_session' doesn't exist")

The above exception was the direct cause of the following exception:

Traceback (most recent call last):
  File "/home5/edumetrics/virtualenv/Edumetrics/Edumetrics/3.10/lib/python3.10/site-packages/django/core/handlers/exception.py", line 47, in inner
    response = get_response(request)
  File "/home5/edumetrics/virtualenv/Edumetrics/Edumetrics/3.10/lib/python3.10/site-packages/django/core/handlers/base.py", line 181, in _get_response
    response = wrapped_callback(request, *callback_args, **callback_kwargs)
  File "/home5/edumetrics/virtualenv/Edumetrics/Edumetrics/3.10/lib/python3.10/site-packages/django/contrib/auth/decorators.py", line 20, in _wrapped_view
    if test_func(request.user):
  File "/home5/edumetrics/virtualenv/Edumetrics/Edumetrics/3.10/lib/python3.10/site-packages/django/contrib/auth/decorators.py", line 44, in <lambda>
    lambda u: u.is_authenticated,
  File "/home5/edumetrics/virtualenv/Edumetrics/Edumetrics/3.10/lib/python3.10/site-packages/django/utils/functional.py", line 246, in inner
    self._setup()
  File "/home5/edumetrics/virtualenv/Edumetrics/Edumetrics/3.10/lib/python3.10/site-packages/django/utils/functional.py", line 382, in _setup
    self._wrapped = self._setupfunc()
  File "/home5/edumetrics/virtualenv/Edumetrics/Edumetrics/3.10/lib/python3.10/site-packages/django/contrib/auth/middleware.py", line 23, in <lambda>
    request.user = SimpleLazyObject(lambda: get_user(request))
  File "/home5/edumetrics/virtualenv/Edumetrics/Edumetrics/3.10/lib/python3.10/site-packages/django/contrib/auth/middleware.py", line 11, in get_user
    request._cached_user = auth.get_user(request)
  File "/home5/edumetrics/virtualenv/Edumetrics/Edumetrics/3.10/lib/python3.10/site-packages/django/contrib/auth/__init__.py", line 177, in get_user
    user_id = _get_user_session_key(request)
  File "/home5/edumetrics/virtualenv/Edumetrics/Edumetrics/3.10/lib/python3.10/site-packages/django/contrib/auth/__init__.py", line 60, in _get_user_session_key
    return get_user_model()._meta.pk.to_python(request.session[SESSION_KEY])
  File "/home5/edumetrics/virtualenv/Edumetrics/Edumetrics/3.10/lib/python3.10/site-packages/django/contrib/sessions/backends/base.py", line 65, in __getitem__
    return self._session[key]
  File "/home5/edumetrics/virtualenv/Edumetrics/Edumetrics/3.10/lib/python3.10/site-packages/django/contrib/sessions/backends/base.py", line 238, in _get_session
    self._session_cache = self.load()
  File "/home5/edumetrics/virtualenv/Edumetrics/Edumetrics/3.10/lib/python3.10/site-packages/django/contrib/sessions/backends/db.py", line 43, in load
    s = self._get_session_from_db()
  File "/home5/edumetrics/virtualenv/Edumetrics/Edumetrics/3.10/lib/python3.10/site-packages/django/contrib/sessions/backends/db.py", line 32, in _get_session_from_db
    return self.model.objects.get(
  File "/home5/edumetrics/virtualenv/Edumetrics/Edumetrics/3.10/lib/python3.10/site-packages/django/db/models/manager.py", line 85, in manager_method
    return getattr(self.get_queryset(), name)(*args, **kwargs)
  File "/home5/edumetrics/virtualenv/Edumetrics/Edumetrics/3.10/lib/python3.10/site-packages/django/db/models/query.py", line 431, in get
    num = len(clone)
  File "/home5/edumetrics/virtualenv/Edumetrics/Edumetrics/3.10/lib/python3.10/site-packages/django/db/models/query.py", line 262, in __len__
    self._fetch_all()
  File "/home5/edumetrics/virtualenv/Edumetrics/Edumetrics/3.10/lib/python3.10/site-packages/django/db/models/query.py", line 1324, in _fetch_all
    self._result_cache = list(self._iterable_class(self))
  File "/home5/edumetrics/virtualenv/Edumetrics/Edumetrics/3.10/lib/python3.10/site-packages/django/db/models/query.py", line 51, in __iter__
    results = compiler.execute_sql(chunked_fetch=self.chunked_fetch, chunk_size=self.chunk_size)
  File "/home5/edumetrics/virtualenv/Edumetrics/Edumetrics/3.10/lib/python3.10/site-packages/django/db/models/sql/compiler.py", line 1169, in execute_sql
    cursor.execute(sql, params)
  File "/home5/edumetrics/virtualenv/Edumetrics/Edumetrics/3.10/lib/python3.10/site-packages/django/db/backends/utils.py", line 98, in execute
    return super().execute(sql, params)
  File "/home5/edumetrics/virtualenv/Edumetrics/Edumetrics/3.10/lib/python3.10/site-packages/django/db/backends/utils.py", line 66, in execute
    return self._execute_with_wrappers(sql, params, many=False, executor=self._execute)
  File "/home5/edumetrics/virtualenv/Edumetrics/Edumetrics/3.10/lib/python3.10/site-packages/django/db/backends/utils.py", line 75, in _execute_with_wrappers
    return executor(sql, params, many, context)
  File "/home5/edumetrics/virtualenv/Edumetrics/Edumetrics/3.10/lib/python3.10/site-packages/django/db/backends/utils.py", line 79, in _execute
    with self.db.wrap_database_errors:
  File "/home5/edumetrics/virtualenv/Edumetrics/Edumetrics/3.10/lib/python3.10/site-packages/django/db/utils.py", line 90, in __exit__
    raise dj_exc_value.with_traceback(traceback) from exc_value
  File "/home5/edumetrics/virtualenv/Edumetrics/Edumetrics/3.10/lib/python3.10/site-packages/django/db/backends/utils.py", line 84, in _execute
    return self.cursor.execute(sql, params)
  File "/home5/edumetrics/virtualenv/Edumetrics/Edumetrics/3.10/lib/python3.10/site-packages/django/db/backends/mysql/base.py", line 73, in execute
    return self.cursor.execute(query, args)
  File "/home5/edumetrics/virtualenv/Edumetrics/Edumetrics/3.10/lib64/python3.10/site-packages/MySQLdb/cursors.py", line 206, in execute
    res = self._query(query)
  File "/home5/edumetrics/virtualenv/Edumetrics/Edumetrics/3.10/lib64/python3.10/site-packages/MySQLdb/cursors.py", line 319, in _query
    db.query(q)
  File "/home5/edumetrics/virtualenv/Edumetrics/Edumetrics/3.10/lib64/python3.10/site-packages/MySQLdb/connections.py", line 254, in query
    _mysql.connection.query(self, query)
django.db.utils.ProgrammingError: (1146, "Table 'edumetrics_database.django_session' doesn't exist")
Requested Range Not Satisfiable: /static/img/parent.jpg
Not Found: /img/favicon.ico
Not Found: /img/favicon.ico
Not Found: /contact/us/img/favicon.ico
Not Found: /auth/signup/img/favicon.ico
Not Found: /img/favicon.ico
[UID:4478][654] Child process with pid: 3964 was killed by signal: 15, core dumped: no
[UID:4478][654] Child process with pid: 3963 was killed by signal: 15, core dumped: no
Invalid HTTP_HOST header: 'www.edu-metrics.com'. You may need to add 'www.edu-metrics.com' to ALLOWED_HOSTS.
Bad Request: /
Requested Range Not Satisfiable: /static/img/parent.jpg
Not Found: /img/favicon.ico
OSError: LSAPI: File error
Not Found: /auth/signup/img/favicon.ico
Internal Server Error: /auth/signup/
Traceback (most recent call last):
  File "/home5/edumetrics/Edumetrics/Edumetrics/Auth/views.py", line 180, in signup
    User.objects.get(email=email)
  File "/home5/edumetrics/virtualenv/Edumetrics/Edumetrics/3.10/lib/python3.10/site-packages/django/db/models/manager.py", line 85, in manager_method
    return getattr(self.get_queryset(), name)(*args, **kwargs)
  File "/home5/edumetrics/virtualenv/Edumetrics/Edumetrics/3.10/lib/python3.10/site-packages/django/db/models/query.py", line 435, in get
    raise self.model.DoesNotExist(
django.contrib.auth.models.User.DoesNotExist: User matching query does not exist.

During handling of the above exception, another exception occurred:

Traceback (most recent call last):
  File "/home5/edumetrics/virtualenv/Edumetrics/Edumetrics/3.10/lib/python3.10/site-packages/django/core/handlers/exception.py", line 47, in inner
    response = get_response(request)
  File "/home5/edumetrics/virtualenv/Edumetrics/Edumetrics/3.10/lib/python3.10/site-packages/django/core/handlers/base.py", line 181, in _get_response
    response = wrapped_callback(request, *callback_args, **callback_kwargs)
  File "/home5/edumetrics/Edumetrics/Edumetrics/Auth/views.py", line 191, in signup
    send_mail(
  File "/home5/edumetrics/virtualenv/Edumetrics/Edumetrics/3.10/lib/python3.10/site-packages/django/core/mail/__init__.py", line 61, in send_mail
    return mail.send()
  File "/home5/edumetrics/virtualenv/Edumetrics/Edumetrics/3.10/lib/python3.10/site-packages/django/core/mail/message.py", line 284, in send
    return self.get_connection(fail_silently).send_messages([self])
  File "/home5/edumetrics/virtualenv/Edumetrics/Edumetrics/3.10/lib/python3.10/site-packages/django/core/mail/backends/smtp.py", line 102, in send_messages
    new_conn_created = self.open()
  File "/home5/edumetrics/virtualenv/Edumetrics/Edumetrics/3.10/lib/python3.10/site-packages/django/core/mail/backends/smtp.py", line 69, in open
    self.connection.login(self.username, self.password)
  File "/opt/alt/python310/lib64/python3.10/smtplib.py", line 750, in login
    raise last_exception
  File "/opt/alt/python310/lib64/python3.10/smtplib.py", line 739, in login
    (code, resp) = self.auth(
  File "/opt/alt/python310/lib64/python3.10/smtplib.py", line 662, in auth
    raise SMTPAuthenticationError(code, resp)
smtplib.SMTPAuthenticationError: (535, b'Incorrect authentication data')
Not Found: /auth/signup-details/1/img/favicon.ico
Not Found: /img/favicon.ico
Not Found: /auth/signup/img/favicon.ico
Not Found: /auth/signup-details/1/img/favicon.ico
Not Found: /auth/signup-details/1/img/favicon.ico
Not Found: /img/favicon.ico
Not Found: /auth/admin-login/img/favicon.ico
Not Found: /robots.txt
Not Found: /img/favicon.ico
Not Found: /index.html
Not Found: /auth/login-parent/img/favicon.ico
Not Found: /auth/login-parent/index.html
Not Found: /auth/login-teacher/img/favicon.ico
Not Found: /auth/login-teacher/index.html
Not Found: /auth/admin-login/img/favicon.ico
Not Found: /auth/admin-login/index.html
Not Found: /auth/signup/img/favicon.ico
Not Found: /auth/signup/index.html
Not Found: /features/img/favicon.ico
Not Found: /features/index.html
Not Found: /contact/us/img/favicon.ico
Not Found: /contact/us/index.html
Not Found: /about/us/img/favicon.ico
Not Found: /about/us/index.html
Not Found: /auth/forgot-password/img/favicon.ico
Not Found: /auth/forgot-password/index.html
Not Found: /robots.txt
