Traceback (most recent call last):
  File "/home5/edumetrics/Edumetrics/Edumetrics/settings.py", line 228, in <module>
    import tzlocal
ModuleNotFoundError: No module named 'tzlocal'

During handling of the above exception, another exception occurred:

Traceback (most recent call last):
  File "/home5/edumetrics/Edumetrics/passenger_wsgi.py", line 8, in <module>
    wsgi = imp.load_source('wsgi', 'Edumetrics/wsgi.py')
  File "/opt/alt/python310/lib64/python3.10/imp.py", line 172, in load_source
    module = _load(spec)
  File "<frozen importlib._bootstrap>", line 719, in _load
  File "<frozen importlib._bootstrap>", line 688, in _load_unlocked
  File "<frozen importlib._bootstrap_external>", line 883, in exec_module
  File "<frozen importlib._bootstrap>", line 241, in _call_with_frames_removed
  File "Edumetrics/wsgi.py", line 7, in <module>
    application = get_wsgi_application()
  File "/home5/edumetrics/virtualenv/Edumetrics/3.10/lib/python3.10/site-packages/django/core/wsgi.py", line 12, in get_wsgi_application
    django.setup(set_prefix=False)
  File "/home5/edumetrics/virtualenv/Edumetrics/3.10/lib/python3.10/site-packages/django/__init__.py", line 19, in setup
    configure_logging(settings.LOGGING_CONFIG, settings.LOGGING)
  File "/home5/edumetrics/virtualenv/Edumetrics/3.10/lib/python3.10/site-packages/django/conf/__init__.py", line 82, in __getattr__
    self._setup(name)
  File "/home5/edumetrics/virtualenv/Edumetrics/3.10/lib/python3.10/site-packages/django/conf/__init__.py", line 69, in _setup
    self._wrapped = Settings(settings_module)
  File "/home5/edumetrics/virtualenv/Edumetrics/3.10/lib/python3.10/site-packages/django/conf/__init__.py", line 170, in __init__
    mod = importlib.import_module(self.SETTINGS_MODULE)
  File "/opt/alt/python310/lib64/python3.10/importlib/__init__.py", line 126, in import_module
    return _bootstrap._gcd_import(name[level:], package, level)
  File "<frozen importlib._bootstrap>", line 1050, in _gcd_import
  File "<frozen importlib._bootstrap>", line 1027, in _find_and_load
  File "<frozen importlib._bootstrap>", line 1006, in _find_and_load_unlocked
  File "<frozen importlib._bootstrap>", line 688, in _load_unlocked
  File "<frozen importlib._bootstrap_external>", line 883, in exec_module
  File "<frozen importlib._bootstrap>", line 241, in _call_with_frames_removed
  File "/home5/edumetrics/Edumetrics/Edumetrics/settings.py", line 230, in <module>
    except pytz.UnknownTimeZoneError:
NameError: name 'pytz' is not defined
Traceback (most recent call last):
  File "/home5/edumetrics/Edumetrics/Edumetrics/settings.py", line 228, in <module>
    import tzlocal
ModuleNotFoundError: No module named 'tzlocal'

During handling of the above exception, another exception occurred:

Traceback (most recent call last):
  File "/home5/edumetrics/Edumetrics/passenger_wsgi.py", line 8, in <module>
    wsgi = imp.load_source('wsgi', 'Edumetrics/wsgi.py')
  File "/opt/alt/python310/lib64/python3.10/imp.py", line 172, in load_source
    module = _load(spec)
  File "<frozen importlib._bootstrap>", line 719, in _load
  File "<frozen importlib._bootstrap>", line 688, in _load_unlocked
  File "<frozen importlib._bootstrap_external>", line 883, in exec_module
  File "<frozen importlib._bootstrap>", line 241, in _call_with_frames_removed
  File "Edumetrics/wsgi.py", line 7, in <module>
    application = get_wsgi_application()
  File "/home5/edumetrics/virtualenv/Edumetrics/3.10/lib/python3.10/site-packages/django/core/wsgi.py", line 12, in get_wsgi_application
    django.setup(set_prefix=False)
  File "/home5/edumetrics/virtualenv/Edumetrics/3.10/lib/python3.10/site-packages/django/__init__.py", line 19, in setup
    configure_logging(settings.LOGGING_CONFIG, settings.LOGGING)
  File "/home5/edumetrics/virtualenv/Edumetrics/3.10/lib/python3.10/site-packages/django/conf/__init__.py", line 82, in __getattr__
    self._setup(name)
  File "/home5/edumetrics/virtualenv/Edumetrics/3.10/lib/python3.10/site-packages/django/conf/__init__.py", line 69, in _setup
    self._wrapped = Settings(settings_module)
  File "/home5/edumetrics/virtualenv/Edumetrics/3.10/lib/python3.10/site-packages/django/conf/__init__.py", line 170, in __init__
    mod = importlib.import_module(self.SETTINGS_MODULE)
  File "/opt/alt/python310/lib64/python3.10/importlib/__init__.py", line 126, in import_module
    return _bootstrap._gcd_import(name[level:], package, level)
  File "<frozen importlib._bootstrap>", line 1050, in _gcd_import
  File "<frozen importlib._bootstrap>", line 1027, in _find_and_load
  File "<frozen importlib._bootstrap>", line 1006, in _find_and_load_unlocked
  File "<frozen importlib._bootstrap>", line 688, in _load_unlocked
  File "<frozen importlib._bootstrap_external>", line 883, in exec_module
  File "<frozen importlib._bootstrap>", line 241, in _call_with_frames_removed
  File "/home5/edumetrics/Edumetrics/Edumetrics/settings.py", line 230, in <module>
    except pytz.UnknownTimeZoneError:
NameError: name 'pytz' is not defined
[UID:4478][7674] Child process with pid: 7771 was killed by signal: 15, core dumped: no
Traceback (most recent call last):
  File "/home5/edumetrics/Edumetrics/Edumetrics/settings.py", line 228, in <module>
    import tzlocal
ModuleNotFoundError: No module named 'tzlocal'

During handling of the above exception, another exception occurred:

Traceback (most recent call last):
  File "/home5/edumetrics/Edumetrics/passenger_wsgi.py", line 8, in <module>
    wsgi = imp.load_source('wsgi', 'Edumetrics/wsgi.py')
  File "/opt/alt/python310/lib64/python3.10/imp.py", line 172, in load_source
    module = _load(spec)
  File "<frozen importlib._bootstrap>", line 719, in _load
  File "<frozen importlib._bootstrap>", line 688, in _load_unlocked
  File "<frozen importlib._bootstrap_external>", line 883, in exec_module
  File "<frozen importlib._bootstrap>", line 241, in _call_with_frames_removed
  File "Edumetrics/wsgi.py", line 7, in <module>
    application = get_wsgi_application()
  File "/home5/edumetrics/virtualenv/Edumetrics/3.10/lib/python3.10/site-packages/django/core/wsgi.py", line 12, in get_wsgi_application
    django.setup(set_prefix=False)
  File "/home5/edumetrics/virtualenv/Edumetrics/3.10/lib/python3.10/site-packages/django/__init__.py", line 19, in setup
    configure_logging(settings.LOGGING_CONFIG, settings.LOGGING)
  File "/home5/edumetrics/virtualenv/Edumetrics/3.10/lib/python3.10/site-packages/django/conf/__init__.py", line 82, in __getattr__
    self._setup(name)
  File "/home5/edumetrics/virtualenv/Edumetrics/3.10/lib/python3.10/site-packages/django/conf/__init__.py", line 69, in _setup
    self._wrapped = Settings(settings_module)
  File "/home5/edumetrics/virtualenv/Edumetrics/3.10/lib/python3.10/site-packages/django/conf/__init__.py", line 170, in __init__
    mod = importlib.import_module(self.SETTINGS_MODULE)
  File "/opt/alt/python310/lib64/python3.10/importlib/__init__.py", line 126, in import_module
    return _bootstrap._gcd_import(name[level:], package, level)
  File "<frozen importlib._bootstrap>", line 1050, in _gcd_import
  File "<frozen importlib._bootstrap>", line 1027, in _find_and_load
  File "<frozen importlib._bootstrap>", line 1006, in _find_and_load_unlocked
  File "<frozen importlib._bootstrap>", line 688, in _load_unlocked
  File "<frozen importlib._bootstrap_external>", line 883, in exec_module
  File "<frozen importlib._bootstrap>", line 241, in _call_with_frames_removed
  File "/home5/edumetrics/Edumetrics/Edumetrics/settings.py", line 230, in <module>
    except pytz.UnknownTimeZoneError:
NameError: name 'pytz' is not defined
[UID:4478][7674] Child process with pid: 7811 was killed by signal: 15, core dumped: no
0.003126685
0.0033174391666666667
0.005021013888888888
0.0263874075
Not Found: /favicon.ico
0.048954721666666666
0.04922792333333334
0.03906373722222223
0.040715040833333334
0.04191711333333334
0.04210439
0.028637583888888887
Africa/Kampala
0.03813086111111111
0.04091102444444444
3.7412322469444446
3.756744934444444
Not Found: /static/img/web.3a512c87d2e4.png
Not Found: /static/img/web.3a512c87d2e4.png
Not Found: /robots.txt
